<sdf version='1.7'>
  <world name='default'>
    <scene>
      <ambient>0.8 0.8 0.8 1</ambient>
      <shadows>0</shadows>
      <grid>0</grid>
      <background>0.7 0.7 0.7 1</background>
    </scene>
    <model name='course'>
      <static>1</static>
      <link name='course_link'>
        <collision name='course_collision'>
          <geometry>
            <plane>
              <normal>0 0 1</normal>
              <size>3.67 2.53</size>
            </plane>
          </geometry>
          <surface>
            <friction>
              <ode>
                <mu>100</mu>
                <mu2>50</mu2>
              </ode>
              <torsional>
                <ode/>
              </torsional>
            </friction>
            <contact>
              <ode/>
            </contact>
            <bounce/>
          </surface>
          <max_contacts>10</max_contacts>
        </collision>
        <visual name='course_visual'>
          <cast_shadows>0</cast_shadows>
          <geometry>
            <plane>
              <normal>0 0 1</normal>
              <size>3.67 2.53</size>
            </plane>
          </geometry>
          <material>
            <script>
              <uri>model://turtlebot3_autorace_2020/course/materials/scripts</uri>
              <uri>model://turtlebot3_autorace_2020/course/materials/textures</uri>
              <name>course</name>
            </script>
          </material>
        </visual>
        <self_collide>0</self_collide>
        <enable_wind>0</enable_wind>
        <kinematic>0</kinematic>
      </link>
      <pose>0 0 0 0 0 -3.14</pose>
    </model>
    <light name='sun' type='directional'>
      <cast_shadows>1</cast_shadows>
      <pose>0 0 10 0 -0 0</pose>
      <diffuse>0.8 0.8 0.8 1</diffuse>
      <specular>0.1 0.1 0.1 1</specular>
      <attenuation>
        <range>1000</range>
        <constant>0.9</constant>
        <linear>0.01</linear>
        <quadratic>0.001</quadratic>
      </attenuation>
      <direction>-0.5 0.5 -1</direction>
      <spot>
        <inner_angle>0</inner_angle>
        <outer_angle>0</outer_angle>
        <falloff>0</falloff>
      </spot>
    </light>
    <model name='ground2'>
      <pose>0 0 -0.1 0 -0 0</pose>
      <static>1</static>
      <link name='ground'>
        <collision name='ground_coll'>
          <geometry>
            <box>
              <size>8 8 0.01</size>
            </box>
          </geometry>
          <surface>
            <contact>
              <ode/>
            </contact>
            <bounce/>
            <friction>
              <torsional>
                <ode/>
              </torsional>
              <ode/>
            </friction>
          </surface>
          <max_contacts>10</max_contacts>
        </collision>
        <visual name='ground_vis'>
          <geometry>
            <box>
              <size>10 10 0.01</size>
            </box>
          </geometry>
          <material>
            <script>
              <uri>file://media/materials/scripts/gazebo.material</uri>
              <name>Gazebo/FlatBlack</name>
            </script>
          </material>
        </visual>
        <self_collide>0</self_collide>
        <kinematic>0</kinematic>
        <gravity>1</gravity>
        <enable_wind>0</enable_wind>
      </link>
    </model>
    <gravity>0 0 -9.8</gravity>
    <magnetic_field>6e-06 2.3e-05 -4.2e-05</magnetic_field>
    <atmosphere type='adiabatic'/>
    <physics name='default_physics' default='0' type='ode'>
      <max_step_size>0.001</max_step_size>
      <real_time_factor>1</real_time_factor>
      <real_time_update_rate>1000</real_time_update_rate>
    </physics>
    <spherical_coordinates>
      <surface_model>EARTH_WGS84</surface_model>
      <latitude_deg>0</latitude_deg>
      <longitude_deg>0</longitude_deg>
      <elevation>0</elevation>
      <heading_deg>0</heading_deg>
    </spherical_coordinates>
    <light name='user_point_light_1' type='point'>
      <pose>-1.64815 0.604519 1 0 -0 0</pose>
      <diffuse>0.5 0.5 0.5 1</diffuse>
      <specular>0.1 0.1 0.1 1</specular>
      <attenuation>
        <range>20</range>
        <constant>0.5</constant>
        <linear>0.01</linear>
        <quadratic>0.001</quadratic>
      </attenuation>
      <cast_shadows>0</cast_shadows>
      <direction>0 0 -1</direction>
      <spot>
        <inner_angle>0</inner_angle>
        <outer_angle>0</outer_angle>
        <falloff>0</falloff>
      </spot>
    </light>
    <light name='user_point_light_2' type='point'>
      <pose>1.63854 1.69565 1 0 -0 0</pose>
      <diffuse>0.5 0.5 0.5 1</diffuse>
      <specular>0.1 0.1 0.1 1</specular>
      <attenuation>
        <range>20</range>
        <constant>0.5</constant>
        <linear>0.01</linear>
        <quadratic>0.001</quadratic>
      </attenuation>
      <cast_shadows>0</cast_shadows>
      <direction>0 0 -1</direction>
      <spot>
        <inner_angle>0</inner_angle>
        <outer_angle>0</outer_angle>
        <falloff>0</falloff>
      </spot>
    </light>
    <light name='user_point_light_3' type='point'>
      <pose>0.42 -3.31 1 0 -0 0</pose>
      <diffuse>0.5 0.5 0.5 1</diffuse>
      <specular>0.1 0.1 0.1 1</specular>
      <attenuation>
        <range>20</range>
        <constant>0.5</constant>
        <linear>0.01</linear>
        <quadratic>0.001</quadratic>
      </attenuation>
      <cast_shadows>0</cast_shadows>
      <direction>0 0 -1</direction>
      <spot>
        <inner_angle>0</inner_angle>
        <outer_angle>0</outer_angle>
        <falloff>0</falloff>
      </spot>
    </light>
    <state world_name='default'>
      <sim_time>3424 719000000</sim_time>
      <real_time>72 141988130</real_time>
      <wall_time>1750137788 947424369</wall_time>
      <iterations>71052</iterations>
      <model name='burger_cam'>
        <pose>0.354223 -1.03731 0.008512 0.000484 0.006095 -0.000388</pose>
        <scale>1 1 1</scale>
        <link name='base_footprint'>
          <pose>0.354223 -1.03731 0.008512 0.000484 0.006095 -0.000388</pose>
          <velocity>-2e-06 9e-06 -0.055608 0.000465 0.000592 -0</velocity>
          <acceleration>0.00052 3.4e-05 -0.895446 -4.7e-05 -0.077038 5e-06</acceleration>
          <wrench>0.00052 3.4e-05 -0.895446 0 -0 0</wrench>
        </link>
        <link name='base_link'>
          <pose>0.354223 -1.03731 0.008512 0.000484 0.006095 -0.000388</pose>
          <velocity>-2e-06 9e-06 -0.055608 0.000465 0.000592 -0</velocity>
          <acceleration>-0.00488 3.7e-05 -0.897862 -4.7e-05 -0.077037 9e-06</acceleration>
          <wrench>-0.00403 3e-05 -0.741396 0 -0 0</wrench>
        </link>
        <link name='base_scan'>
          <pose>0.354223 -1.03731 0.008512 0.000484 0.006095 -0.000388</pose>
          <velocity>-2e-06 9e-06 -0.055608 0.000465 0.000592 -0</velocity>
          <acceleration>-0.011861 4.1e-05 -0.896865 -4.6e-05 -0.077061 5e-06</acceleration>
          <wrench>-0.001352 5e-06 -0.102243 0 -0 0</wrench>
        </link>
        <link name='camera_link'>
          <pose>0.430788 -1.03739 0.101047 0.000484 0.006095 -0.000388</pose>
          <velocity>5.3e-05 -3.4e-05 -0.055654 0.000465 0.000592 -0</velocity>
          <acceleration>-0.013706 4.3e-05 -0.883593 -4.6e-05 -0.076994 4e-06</acceleration>
          <wrench>-0.00048 2e-06 -0.030926 0 -0 0</wrench>
        </link>
        <link name='caster_back_link'>
          <pose>0.2732 -1.03728 0.005005 -2.92152 -0.844772 0.669581</pose>
          <velocity>-3e-06 1e-05 -0.055491 -0.001631 -0.001668 0</velocity>
          <acceleration>0.00051 0.00038 -0.918948 0 -0 0</acceleration>
          <wrench>3e-06 2e-06 -0.004595 0 -0 0</wrench>
        </link>
        <link name='imu_link'>
          <pose>0.354223 -1.03731 0.008512 0.000484 0.006095 -0.000388</pose>
          <velocity>-2e-06 9e-06 -0.055609 0.000465 0.000592 -0</velocity>
          <acceleration>0.000556 3.4e-05 -0.89536 -4.7e-05 -0.077033 5e-06</acceleration>
          <wrench>0.000556 3.4e-05 -0.89536 0 -0 0</wrench>
        </link>
        <link name='wheel_left_link'>
          <pose>0.353808 -1.03731 0.008518 0.000485 0.024165 -0.000365</pose>
          <velocity>6e-06 -5e-06 -0.055608 0.000458 0.000593 0</velocity>
          <acceleration>-0.002519 2e-06 -0.895284 -6.3e-05 -0.076341 8e-06</acceleration>
          <wrench>-7.2e-05 0 -0.025515 0 -0 0</wrench>
        </link>
        <link name='wheel_right_link'>
          <pose>0.353763 -1.03731 0.008519 0.000485 0.02601 -0.000363</pose>
          <velocity>6e-06 -5e-06 -0.05561 0.000458 0.000593 0</velocity>
          <acceleration>-0.002519 2e-06 -0.895289 -6.5e-05 -0.076327 5e-06</acceleration>
          <wrench>-7.2e-05 0 -0.025515 0 -0 0</wrench>
        </link>
      </model>
      <model name='course'>
        <pose>0 0 0 0 0 -3.14</pose>
        <scale>1 1 1</scale>
        <link name='course_link'>
          <pose>0 0 0 0 0 -3.14</pose>
          <velocity>0 0 0 0 -0 0</velocity>
          <acceleration>0 0 0 0 -0 0</acceleration>
          <wrench>0 0 0 0 -0 0</wrench>
        </link>
      </model>
      <model name='enclosure'>
        <pose>1.01752 -1.48944 0 0 -0 0</pose>
        <scale>1 1 1</scale>
      </model>
      <model name='enclosure_0'>
        <pose>0.155995 -0.030154 0 0 -0 0</pose>
        <scale>1 1 1</scale>
      </model>
      <model name='ground2'>
        <pose>0.004281 0.047958 -0.1 0 -0 0</pose>
        <scale>1 1 1</scale>
        <link name='ground'>
          <pose>0.004281 0.047958 -0.1 0 -0 0</pose>
          <velocity>0 0 0 0 -0 0</velocity>
          <acceleration>0 0 0 0 -0 0</acceleration>
          <wrench>0 0 0 0 -0 0</wrench>
        </link>
      </model>
      <light name='sun'>
        <pose>0 0 10 0 -0 0</pose>
      </light>
      <light name='user_point_light_1'>
        <pose>-1.64815 0.604519 1 0 -0 0</pose>
      </light>
      <light name='user_point_light_2'>
        <pose>1.63854 1.69565 1 0 -0 0</pose>
      </light>
      <light name='user_point_light_3'>
        <pose>0.42 -3.31 1 0 -0 0</pose>
      </light>
    </state>
    <gui fullscreen='0'>
      <camera name='user_camera'>
        <pose>3.18384 -0.121023 2.50886 0 0.785797 3.13581</pose>
        <view_controller>orbit</view_controller>
        <projection_type>perspective</projection_type>
      </camera>
    </gui>
    <audio>
      <device>default</device>
    </audio>
    <wind/>
    <model name='burger_cam'>
      <pose>0.8 -1.747 0.01 0 -0 0</pose>
      <link name='base_footprint'>
        <self_collide>0</self_collide>
        <inertial>
          <pose>0 0 0 0 -0 0</pose>
          <inertia>
            <ixx>1</ixx>
            <ixy>0</ixy>
            <ixz>0</ixz>
            <iyy>1</iyy>
            <iyz>0</iyz>
            <izz>1</izz>
          </inertia>
          <mass>1</mass>
        </inertial>
        <enable_wind>0</enable_wind>
        <kinematic>0</kinematic>
      </link>
      <link name='base_link'>
        <inertial>
          <pose>-0.032 0 0.07 0 -0 0</pose>
          <inertia>
            <ixx>0.723974</ixx>
            <ixy>4.6864e-10</ixy>
            <ixz>-1.09526e-08</ixz>
            <iyy>0.723974</iyy>
            <iyz>2.85826e-09</iyz>
            <izz>0.65305</izz>
          </inertia>
          <mass>0.825735</mass>
        </inertial>
        <collision name='base_collision'>
          <pose>-0.032 0 0.07 0 -0 0</pose>
          <geometry>
            <box>
              <size>0.14 0.14 0.14</size>
            </box>
          </geometry>
          <max_contacts>10</max_contacts>
          <surface>
            <contact>
              <ode/>
            </contact>
            <bounce/>
            <friction>
              <torsional>
                <ode/>
              </torsional>
              <ode/>
            </friction>
          </surface>
        </collision>
        <visual name='base_visual'>
          <pose>-0.032 0 0 0 -0 0</pose>
          <geometry>
            <mesh>
              <uri>model://turtlebot3_common/meshes/bases/burger_base.stl</uri>
              <scale>0.001 0.001 0.001</scale>
            </mesh>
          </geometry>
          <material>
            <ambient>0.3 0.3 0.3 1</ambient>
            <diffuse>0.3 0.3 0.3 1</diffuse>
          </material>
        </visual>
        <self_collide>0</self_collide>
        <enable_wind>0</enable_wind>
        <kinematic>0</kinematic>
      </link>
      <link name='imu_link'>
        <sensor name='tb3_imu' type='imu'>
          <always_on>1</always_on>
          <update_rate>200</update_rate>
          <imu>
            <angular_velocity>
              <x>
                <noise type='gaussian'>
                  <mean>0</mean>
                  <stddev>0.0002</stddev>
                </noise>
              </x>
              <y>
                <noise type='gaussian'>
                  <mean>0</mean>
                  <stddev>0.0002</stddev>
                </noise>
              </y>
              <z>
                <noise type='gaussian'>
                  <mean>0</mean>
                  <stddev>0.0002</stddev>
                </noise>
              </z>
            </angular_velocity>
            <linear_acceleration>
              <x>
                <noise type='gaussian'>
                  <mean>0</mean>
                  <stddev>0.017</stddev>
                </noise>
              </x>
              <y>
                <noise type='gaussian'>
                  <mean>0</mean>
                  <stddev>0.017</stddev>
                </noise>
              </y>
              <z>
                <noise type='gaussian'>
                  <mean>0</mean>
                  <stddev>0.017</stddev>
                </noise>
              </z>
            </linear_acceleration>
          </imu>
          <plugin name='turtlebot3_imu' filename='libgazebo_ros_imu_sensor.so'>
            <ros>
              <remapping>~/out:=imu</remapping>
            </ros>
          </plugin>
        </sensor>
        <self_collide>0</self_collide>
        <inertial>
          <pose>0 0 0 0 -0 0</pose>
          <inertia>
            <ixx>1</ixx>
            <ixy>0</ixy>
            <ixz>0</ixz>
            <iyy>1</iyy>
            <iyz>0</iyz>
            <izz>1</izz>
          </inertia>
          <mass>1</mass>
        </inertial>
        <enable_wind>0</enable_wind>
        <kinematic>0</kinematic>
      </link>
      <link name='base_scan'>
        <inertial>
          <pose>-0.02 0 0.161 0 -0 0</pose>
          <inertia>
            <ixx>0.001</ixx>
            <ixy>0</ixy>
            <ixz>0</ixz>
            <iyy>0.001</iyy>
            <iyz>0</iyz>
            <izz>0.001</izz>
          </inertia>
          <mass>0.114</mass>
        </inertial>
        <collision name='lidar_sensor_collision'>
          <pose>-0.02 0 0.161 0 -0 0</pose>
          <geometry>
            <cylinder>
              <radius>0.0508</radius>
              <length>0.055</length>
            </cylinder>
          </geometry>
          <max_contacts>10</max_contacts>
          <surface>
            <contact>
              <ode/>
            </contact>
            <bounce/>
            <friction>
              <torsional>
                <ode/>
              </torsional>
              <ode/>
            </friction>
          </surface>
        </collision>
        <visual name='lidar_sensor_visual'>
          <pose>-0.032 0 0.171 0 -0 0</pose>
          <geometry>
            <mesh>
              <uri>model://turtlebot3_common/meshes/sensors/lds.stl</uri>
              <scale>0.001 0.001 0.001</scale>
            </mesh>
          </geometry>
          <material>
            <ambient>0.2 0.2 0.2 1</ambient>
            <diffuse>0.2 0.2 0.2 1</diffuse>
          </material>
        </visual>
        <sensor name='hls_lfcd_lds' type='ray'>
          <always_on>1</always_on>
          <visualize>0</visualize>
          <pose>-0.032 0 0.171 0 -0 0</pose>
          <update_rate>5</update_rate>
          <ray>
            <scan>
              <horizontal>
                <samples>360</samples>
                <resolution>1</resolution>
                <min_angle>0</min_angle>
                <max_angle>6.28</max_angle>
              </horizontal>
              <vertical>
                <samples>1</samples>
                <min_angle>0</min_angle>
                <max_angle>0</max_angle>
              </vertical>
            </scan>
            <range>
              <min>0.12</min>
              <max>3.5</max>
              <resolution>0.015</resolution>
            </range>
            <noise>
              <type>gaussian</type>
              <mean>0</mean>
              <stddev>0.01</stddev>
            </noise>
          </ray>
          <plugin name='turtlebot3_laserscan' filename='libgazebo_ros_ray_sensor.so'>
            <ros>
              <remapping>~/out:=scan</remapping>
            </ros>
            <output_type>sensor_msgs/LaserScan</output_type>
            <frame_name>base_scan</frame_name>
          </plugin>
        </sensor>
        <self_collide>0</self_collide>
        <enable_wind>0</enable_wind>
        <kinematic>0</kinematic>
      </link>
      <link name='wheel_left_link'>
        <inertial>
          <pose>0 0.08 0.023 -1.57 0 0</pose>
          <inertia>
            <ixx>0.00181582</ixx>
            <ixy>-9.3392e-12</ixy>
            <ixz>1.04909e-11</ixz>
            <iyy>0.00329221</iyy>
            <iyz>5.75694e-11</iyz>
            <izz>0.00181582</izz>
          </inertia>
          <mass>0.0284989</mass>
        </inertial>
        <collision name='wheel_left_collision'>
          <pose>0 0.08 0.023 -1.57 0 0</pose>
          <geometry>
            <cylinder>
              <radius>0.033</radius>
              <length>0.018</length>
            </cylinder>
          </geometry>
          <surface>
            <friction>
              <ode>
                <mu>100000</mu>
                <mu2>100000</mu2>
                <fdir1>0 0 0</fdir1>
                <slip1>0</slip1>
                <slip2>0</slip2>
              </ode>
              <torsional>
                <ode/>
              </torsional>
            </friction>
            <contact>
              <ode>
                <soft_cfm>0</soft_cfm>
                <soft_erp>0.2</soft_erp>
                <kp>100000</kp>
                <kd>1</kd>
                <max_vel>0.01</max_vel>
                <min_depth>0.001</min_depth>
              </ode>
            </contact>
            <bounce/>
          </surface>
          <max_contacts>10</max_contacts>
        </collision>
        <visual name='wheel_left_visual'>
          <pose>0 0.08 0.023 0 -0 0</pose>
          <geometry>
            <mesh>
              <uri>model://turtlebot3_common/meshes/wheels/left_tire.stl</uri>
              <scale>0.001 0.001 0.001</scale>
            </mesh>
          </geometry>
          <material>
            <ambient>0.2 0.2 0.2 1</ambient>
            <diffuse>0.2 0.2 0.2 1</diffuse>
          </material>
        </visual>
        <self_collide>0</self_collide>
        <enable_wind>0</enable_wind>
        <kinematic>0</kinematic>
      </link>
      <link name='wheel_right_link'>
        <inertial>
          <pose>0 -0.08 0.023 -1.57 0 0</pose>
          <inertia>
            <ixx>0.00181582</ixx>
            <ixy>-9.3392e-12</ixy>
            <ixz>1.04909e-11</ixz>
            <iyy>0.00329221</iyy>
            <iyz>5.75694e-11</iyz>
            <izz>0.00181582</izz>
          </inertia>
          <mass>0.0284989</mass>
        </inertial>
        <collision name='wheel_right_collision'>
          <pose>0 -0.08 0.023 -1.57 0 0</pose>
          <geometry>
            <cylinder>
              <radius>0.033</radius>
              <length>0.018</length>
            </cylinder>
          </geometry>
          <surface>
            <friction>
              <ode>
                <mu>100000</mu>
                <mu2>100000</mu2>
                <fdir1>0 0 0</fdir1>
                <slip1>0</slip1>
                <slip2>0</slip2>
              </ode>
              <torsional>
                <ode/>
              </torsional>
            </friction>
            <contact>
              <ode>
                <soft_cfm>0</soft_cfm>
                <soft_erp>0.2</soft_erp>
                <kp>100000</kp>
                <kd>1</kd>
                <max_vel>0.01</max_vel>
                <min_depth>0.001</min_depth>
              </ode>
            </contact>
            <bounce/>
          </surface>
          <max_contacts>10</max_contacts>
        </collision>
        <visual name='wheel_right_visual'>
          <pose>0 -0.08 0.023 0 -0 0</pose>
          <geometry>
            <mesh>
              <uri>model://turtlebot3_common/meshes/wheels/right_tire.stl</uri>
              <scale>0.001 0.001 0.001</scale>
            </mesh>
          </geometry>
          <material>
            <ambient>0.2 0.2 0.2 1</ambient>
            <diffuse>0.2 0.2 0.2 1</diffuse>
          </material>
        </visual>
        <self_collide>0</self_collide>
        <enable_wind>0</enable_wind>
        <kinematic>0</kinematic>
      </link>
      <link name='caster_back_link'>
        <pose>-0.081 0 -0.004 -1.57 0 0</pose>
        <inertial>
          <mass>0.005</mass>
          <inertia>
            <ixx>0.001</ixx>
            <ixy>0</ixy>
            <ixz>0</ixz>
            <iyy>0.001</iyy>
            <iyz>0</iyz>
            <izz>0.001</izz>
          </inertia>
          <pose>0 0 0 0 -0 0</pose>
        </inertial>
        <collision name='collision'>
          <geometry>
            <sphere>
              <radius>0.005</radius>
            </sphere>
          </geometry>
          <surface>
            <contact>
              <ode>
                <soft_cfm>0</soft_cfm>
                <soft_erp>0.2</soft_erp>
                <kp>100000</kp>
                <kd>1</kd>
                <max_vel>0.01</max_vel>
                <min_depth>0.001</min_depth>
              </ode>
            </contact>
            <bounce/>
            <friction>
              <torsional>
                <ode/>
              </torsional>
              <ode/>
            </friction>
          </surface>
          <max_contacts>10</max_contacts>
        </collision>
        <self_collide>0</self_collide>
        <enable_wind>0</enable_wind>
        <kinematic>0</kinematic>
      </link>
      <link name='camera_link'>
        <inertial>
          <pose>0.076 0 0.093 0 -0 0</pose>
          <inertia>
            <ixx>0.001</ixx>
            <ixy>0</ixy>
            <ixz>0</ixz>
            <iyy>0.001</iyy>
            <iyz>0</iyz>
            <izz>0.001</izz>
          </inertia>
          <mass>0.035</mass>
        </inertial>
        <pose>0.076 0 0.093 0 -0 0</pose>
        <sensor name='camera' type='wideanglecamera'>
          <always_on>1</always_on>
          <visualize>1</visualize>
          <update_rate>30</update_rate>
          <camera name='picam'>
            <horizontal_fov>3.183</horizontal_fov>
            <image>
              <width>320</width>
              <height>240</height>
              <format>R8G8B8</format>
            </image>
            <clip>
              <near>0.03</near>
              <far>100</far>
            </clip>
            <lens>
              <type>custom</type>
              <custom_function>
                <c1>1.05</c1>
                <c2>4</c2>
                <f>1</f>
                <fun>tan</fun>
              </custom_function>
              <scale_to_hfov>1</scale_to_hfov>
              <cutoff_angle>3.1415</cutoff_angle>
              <env_texture_size>512</env_texture_size>
            </lens>
          </camera>
          <plugin name='camera_driver' filename='libgazebo_ros_camera.so'>
            <alwaysOn>1</alwaysOn>
            <updateRate>30.0</updateRate>
            <cameraName>camera</cameraName>
            <frameName>camera_link</frameName>
            <imageTopicName>image_raw</imageTopicName>
            <cameraInfoTopicName>camera_info</cameraInfoTopicName>
            <hackBaseline>0.07</hackBaseline>
            <distortionK1>0.0</distortionK1>
            <distortionK2>0.0</distortionK2>
            <distortionK3>0.0</distortionK3>
            <distortionT1>0.0</distortionT1>
            <distortionT2>0.0</distortionT2>
            <ros/>
          </plugin>
        </sensor>
        <self_collide>0</self_collide>
        <enable_wind>0</enable_wind>
        <kinematic>0</kinematic>
      </link>
      <joint name='base_joint' type='fixed'>
        <parent>base_footprint</parent>
        <child>base_link</child>
        <pose>0 0 0.01 0 -0 0</pose>
      </joint>
      <joint name='wheel_left_joint' type='revolute'>
        <parent>base_link</parent>
        <child>wheel_left_link</child>
        <pose>0 0.08 0.023 -1.57 0 0</pose>
        <axis>
          <xyz>0 0 1</xyz>
          <limit>
            <lower>-1e+16</lower>
            <upper>1e+16</upper>
          </limit>
          <dynamics>
            <spring_reference>0</spring_reference>
            <spring_stiffness>0</spring_stiffness>
          </dynamics>
        </axis>
      </joint>
      <joint name='wheel_right_joint' type='revolute'>
        <parent>base_link</parent>
        <child>wheel_right_link</child>
        <pose>0 -0.08 0.023 -1.57 0 0</pose>
        <axis>
          <xyz>0 0 1</xyz>
          <limit>
            <lower>-1e+16</lower>
            <upper>1e+16</upper>
          </limit>
          <dynamics>
            <spring_reference>0</spring_reference>
            <spring_stiffness>0</spring_stiffness>
          </dynamics>
        </axis>
      </joint>
      <joint name='caster_back_joint' type='ball'>
        <parent>base_link</parent>
        <child>caster_back_link</child>
      </joint>
      <joint name='imu_joint' type='fixed'>
        <parent>base_link</parent>
        <child>imu_link</child>
        <pose>-0.032 0 0.068 0 -0 0</pose>
        <axis>
          <xyz>0 0 1</xyz>
          <limit>
            <lower>-1e+16</lower>
            <upper>1e+16</upper>
          </limit>
        </axis>
      </joint>
      <joint name='lidar_joint' type='fixed'>
        <parent>base_link</parent>
        <child>base_scan</child>
        <pose>-0.032 0 0.171 0 -0 0</pose>
        <axis>
          <xyz>0 0 1</xyz>
          <limit>
            <lower>-1e+16</lower>
            <upper>1e+16</upper>
          </limit>
        </axis>
      </joint>
      <joint name='camera_joint' type='fixed'>
        <parent>base_link</parent>
        <child>camera_link</child>
        <pose>0.04 -0 0.11 0 -0 0</pose>
        <axis>
          <xyz>0 0 1</xyz>
          <limit>
            <lower>-1e+16</lower>
            <upper>1e+16</upper>
          </limit>
        </axis>
      </joint>
      <plugin name='turtlebot3_diff_drive' filename='libgazebo_ros_diff_drive.so'>
        <ros/>
        <update_rate>30</update_rate>
        <left_joint>wheel_left_joint</left_joint>
        <right_joint>wheel_right_joint</right_joint>
        <wheel_separation>0.160</wheel_separation>
        <wheel_diameter>0.066</wheel_diameter>
        <max_wheel_torque>20</max_wheel_torque>
        <max_wheel_acceleration>1.0</max_wheel_acceleration>
        <command_topic>cmd_vel</command_topic>
        <publish_odom>1</publish_odom>
        <publish_odom_tf>1</publish_odom_tf>
        <publish_wheel_tf>0</publish_wheel_tf>
        <odometry_topic>odom</odometry_topic>
        <odometry_frame>odom</odometry_frame>
        <robot_base_frame>base_footprint</robot_base_frame>
      </plugin>
      <plugin name='turtlebot3_joint_state' filename='libgazebo_ros_joint_state_publisher.so'>
        <ros>
          <remapping>~/out:=joint_states</remapping>
        </ros>
        <update_rate>30</update_rate>
        <joint_name>wheel_left_joint</joint_name>
        <joint_name>wheel_right_joint</joint_name>
      </plugin>
    </model>
    <model name='enclosure'>
      <pose>1.01752 -1.48944 0 0 -0 0</pose>
    </model>
    <model name='enclosure_0'>
      <pose>0.155995 -0.030154 0 0 -0 0</pose>
    </model>
    <physics type='ode'>
      <max_step_size>0.001</max_step_size>
      <real_time_factor>1</real_time_factor>
      <real_time_update_rate>1000</real_time_update_rate>
      <solver>
        <type>world</type>
        <iters>150</iters>
        <precon_iters>75</precon_iters>
      </solver>
    </physics>
  </world>
</sdf>
